Workbook
Name ListaDocentes: OFFSET(Docentes!$A$2,0,0,MAX(1,COUNTA(Docentes!$A$2:$A$251)),1)

Sheet Portada
A1: REGISTRO DE VACANTES Y REFUERZOS
A2: Enseñanzas elementales y profesionales de Música · vacantes de cualquier origen, su vía de cobertura y las horas usadas como refuerzo
A4: Centro | C4: obligatorio · escribe aquí el nombre del centro
A5: Código del centro | C5: obligatorio · el código de centro de la GVA; aparece en la cabecera de todos los informes
A6: Curso académico | B6: 2026-2027 | C6: revísalo cada septiembre
A7: Hoy es | B7: =TODAY()
A8: Fin del 2.º trimestre | C8: obligatorio · lo fija el centro en su PGA; habitualmente, el último día lectivo antes de Pascua
A9: =IF($B$8="","Falta la fecha de fin del 2.º trimestre, aquí arriba","Lista de espera: "&IF(TODAY()<=DATE(IF(MONTH(TODAY())>=9,YEAR(TODAY()),YEAR(TODAY())-1),12,15),"ABIERTA hasta el 15 de diciembre","CERRADA desde el 16 de diciembre")&" · Traslado de expediente: "&IF(TODAY()<=$B$8,"ABIERTO hasta el fin del 2.º trimestre","CERRADO")&IF(AND(TODAY()>DATE(IF(MONTH(TODAY())>=9,YEAR(TODAY()),YEAR(TODAY())-1),12,15),TODAY()>$B$8)," · Solo queda la vía excepcional de la dirección territorial",""))
A10: CÓMO SE CUBRE UNA VACANTE, SEGÚN LA FECHA
A11: Plazo | B11: Qué ocurre | C11: Detalle
A12: hasta el 30 de noviembre | B12: Renuncia de matrícula | C12: No computa a efectos de permanencia
A13: desde el 1 de diciembre | B13: Baja de matrícula | C13: Consume convocatoria
A14: hasta el 15 de diciembre | B14: Lista de espera | C14: 1.º propio centro · 2.º otros centros
A15: hasta el fin del 2.º trimestre | B15: Traslado de expediente | C15: Con lista de espera propia por especialidad
A16: después | B16: Solo vía excepcional | C16: Resuelve la dirección territorial
A18: Versión 1.1 · CC BY 4.0 · github.com/JLMirallesB/registro-vacantes-conservatorio
A19: Construido sobre la Orden 8/2026, de 24 de abril (DOGV 10352). El detalle del proceso, en la nota de centro.

Sheet Instrucciones
A1: INSTRUCCIONES
A2: Registro de vacantes y refuerzos · léelo una vez antes de empezar
A4: QUÉ VA EN CADA HOJA
A5: La regla | B5: Si un alumno nuevo podría sentarse en esa hora, va a Registro. Si no hay plaza que ofertar (asignaturas que no son de especialidad), va a Registro Refuerzo. Nunca en las dos: el Contador la sumaría dos veces y nadie se daría cuenta.
A6: Hoja Registro | B6: Cualquier hueco horario libre que alguien podría ocupar: por baja, renuncia o traslado; porque la plaza no se adjudicó; o porque esa hora nunca tuvo alumnado. Aquí va también el apoyo instrumental a alumnado ya matriculado: se registra como vacante y se marca «No disponible», porque esa hora no se puede ofertar.
A7: Hoja Registro Refuerzo | B7: Solo las horas de refuerzo de asignaturas que no son de especialidad —Lenguaje Musical, Armonía/Análisis e Historia—, donde no hay ninguna plaza que ofrecer porque la matrícula va con el instrumento.
A9: CÓMO SE RELLENA
A10: Una fila por especialidad | B10: Cada fila es un hueco horario. Si un alumno se da de baja de dos especialidades, son dos filas: la normativa permite renunciar a cada una por separado.
A11: Empieza por la especialidad | B11: Hasta que no la eliges, la fila no se numera ni reclama nada. Es lo que enciende la fila.
A12: La columna Comprobación | B12: La última por la derecha. Dice «Falta:» y lo que queda por rellenar, «Revisar:» si hay algo que se contradice, o «Completa». Filtra esa columna y tienes la lista de trabajo pendiente; el Dashboard te dice cuántas filas son.
A13: La fecha de hoy, de una tecla | B13: En Windows y en Mac: Ctrl + ; · Ojo en Mac: ⌘ + ; escribe la HORA, no la fecha. No hay calendario desplegable porque Excel no tiene ninguno.
A14: Disponible y en refuerzo a la vez | B14: Es normal y correcto: mientras el hueco está libre puede aprovecharse como refuerzo, y sigue estando disponible por si llega un traslado. Cuando se cubra de verdad, pon «No» en «¿En uso como refuerzo?». Si no lo haces, la columna Comprobación te avisará con «Revisar: la plaza ya tiene alumno y sigue marcada como refuerzo».
A16: LO QUE NO SE TOCA
A17: Borra el contenido, nunca la fila | B17: Selecciona y pulsa Supr. Eliminar la fila entera está bloqueado a propósito: encogería el rango de todas las fórmulas del libro y el registro perdería capacidad en silencio. Ordenar también está bloqueado, por la misma razón.
A18: Columnas calculadas | B18: «Nº de orden» y «Comprobación» se calculan solas y están bloqueadas. «Nuevo Horario» también se calcula —copia el horario original— pero puedes escribir encima si el horario cambia. Entre las columnas visibles hay otras ocultas que son el motor del Dashboard y de los informes: no las muestres ni las borres.
A19: El Nº de orden no identifica | B19: Es la posición en la hoja: si se borra algo, cambia. Para referirte a un caso concreto usa el NIA.
A20: Si necesitas desproteger | B20: Revisar → Desproteger hoja. NO hay contraseña: la protección es un seguro contra accidentes, no un candado. Al terminar, vuelve a protegerla desde Revisar → Proteger hoja, sin escribir ninguna contraseña y dejando las casillas como estaban. Y si tocas fórmulas, prueba antes en una copia.
A22: QUÉ SIGNIFICAN LOS COLORES
A23: Ámbar | B23: Falta algo. La fila entera en ámbar pálido; la celda concreta que falta, en ámbar fuerte.
A24: Rojo | B24: Hay algo que se contradice. Mira la columna Comprobación, que te dice qué.
A25: Verde | B25: Vacante disponible y con todos sus datos.
A26: Crema | B26: En trámite.
A27: Gris apagado | B27: No disponible: la fila se aparta de la vista porque ya no requiere acción.
A28: Rojo en la Portada | B28: Falta el nombre del centro, su código, o la fecha de fin del 2.º trimestre. Sin esa fecha, el aviso de plazos del Dashboard no puede funcionar.
A30: CADA CURSO, Y CUANDO CAMBIE ALGO
A31: En septiembre | B31: Actualiza en la Portada el curso académico y la fecha de fin del 2.º trimestre, que la fija cada centro en su PGA. El nombre y el código del centro se ponen una sola vez.
A32: Hoja Docentes | B32: No hace falta meterlos todos de golpe. Si ya tienes la lista en otro Excel, pégala; si no, ve añadiendo cada docente la primera vez que lo necesites y aparecerá en el desplegable. Eso sí: uno por fila y sin dejar huecos, porque el desplegable cuenta las filas escritas y un hueco corta la lista.
A33: Quién puede escribir en el libro | B33: La lista está en el Dashboard, al final del todo, bajo el rótulo «QUIÉN PUEDE ESCRIBIR EN EL LIBRO» (filas 44 a 50). Cámbiala ahí y los desplegables de las dos hojas de registro se actualizan solos. Hay dos casillas libres para añadir las tuyas.
A34: Añadir o quitar una especialidad | B34: No lo hagas a mano. Obliga a tocar seis hojas cuadrando la correspondencia de filas una a una, y si solo cambias la lista de Validaciones el Dashboard queda desalineado sin dar ningún error. Pídeselo a quien mantiene el libro, o abre un aviso en el repositorio.
A36: QUIÉN LO HA HECHO
A37: Autor | B37: Versión 1.1 · Excel creado por José Luis Miralles Bono; con ayuda de Claude.
A38: Contacto | B38: joseluismirallesbono@gmail.com
A39: Repositorio | B39: https://github.com/JLMirallesB/registro-vacantes-conservatorio · ahí están las versiones, los avisos de fallos y las mejoras en marcha.
A40: Licencia | B40: CC BY 4.0 (Creative Commons Reconocimiento). Puedes usarlo, adaptarlo y repartirlo, también con fines comerciales, siempre que reconozcas la autoría e indiques si lo has cambiado.
A41: ¿Te ha servido? | B41: Invítame a una orxata: https://ko-fi.com/miralles
A42: Los plazos para cubrir una vacante están en la Portada, y el Dashboard te dice cuáles siguen abiertos hoy.

Sheet Docentes
A1: Docentes del centro
B2: Escribe aquí un docente por fila, sin dejar huecos. Esta lista alimenta el desplegable «Nombre del Docente» de las dos hojas de registro.

Sheet Validaciones
A1: Especialidades | B1: Cursos | C1: Motivo de Vacante | D1: Estado Vacante | E1: Sí/No | F1: Duración | G1: Especialidades teóricas (refuerzo) | H1: Estado Refuerzo | I1: Vía de cobertura | J1: Datos personales
A2: ACORDEÓN | B2: EEM 1º | C2: No adjudicada · sin demanda | D2: Disponible | E2: Sí | F2: 30 minutos | G2: LENGUAJE MUSICAL | H2: Activo | I2: Lista de espera · propio centro | J2: Visibles
A3: ARPA | B3: EEM 2º | C3: Adjudicada y no matriculada (art. 23.3) | D3: En trámite | E3: No | F3: 1 hora | G3: ARMONÍA/ANÁLISIS | H3: No activo | I3: Traslado de expediente | J3: Anonimizados
A4: BAJO ELÉCTRICO | B4: EEM 3º | C4: Renuncia (hasta 30 nov) | D4: No disponible | G4: HISTORIA | I4: Lista de espera · otro centro
A5: CANTO | B5: EEM 4º | C5: Baja (desde 1 dic) | I5: Reconvertida en refuerzo
A6: CANTO VALENCIANO | B6: EPM 1º | C6: Renuncia excepcional (art. 25.3) | I6: No cubierta
A7: CLARINETE | B7: EPM 2º | C7: Traslado de expediente
A8: CLAVICÉMBALO | B8: EPM 3º | C8: Hora que nunca tuvo alumnado
A9: CONTRABAJO | B9: EPM 4º | C9: Otros
A10: DOLÇAINA | B10: EPM 5º
A11: FAGOT | B11: EPM 6º
A12: FLAUTA DE PICO
A13: FLAUTA TRAVERSA
A14: GUITARRA
A15: GUITARRA ELÉCTRICA
A16: INSTRUMENTOS DE CUERDA PULSADA DEL RENACIMIENTO Y BARROCO
A17: INSTRUMENTOS DE PLECTRO
A18: OBOE
A19: ÓRGANO
A20: PERCUSIÓN
A21: PIANO
A22: SAXOFÓN
A23: TROMBÓN DE VARAS
... A30: VIOLONCHELO

Sheet Dashboard
A1: PANEL DE CONTROL · VACANTES Y REFUERZOS
A2: =Portada!$A$9
A3: VACANTES DISPONIBLES POR ESPECIALIDAD
A4: Especialidad | B4: Disponibles | C4: Docente y horario disponible
A5: ACORDEÓN | B5: =COUNTIFS(Registro!$D$2:$D$501,A5,Registro!$Q$2:$Q$501,"Disponible") -> 0 | C5: =IF(B5=0,"Sin vacantes",Aux!B2 & IF(Aux!C2<>""," | "&Aux!C2,"") & IF(Aux!D2<>""," | "&Aux!D2,"") & IF(Aux!E2<>""," | "&Aux!E2,"") & IF(Aux!F2<>""," | "&Aux!F2,"") & IF(Aux!G2<>""," | "&Aux!G2,"") & IF(Aux!H2<>""," | "&Aux!H2,"") & IF(Aux!I2<>""," | "&Aux!I2,"") & IF(Aux!J2<>""," | "&Aux!J2,"") & IF(Aux!K2<>""," | "&Aux!K2,"") & IF(Aux!L2<>""," | "&Aux!L2,"") & IF(Aux!M2<>""," | "&Aux!M2,"") & IF(B5>12," | (+"&(B5-12)&" más)",""))
A6: ARPA | B6: =COUNTIFS(Registro!$D$2:$D$501,A6,Registro!$Q$2:$Q$501,"Disponible") -> 0 | C6: =IF(B6=0,"Sin vacantes",Aux!B3 & IF(Aux!C3<>""," | "&Aux!C3,"") & IF(Aux!D3<>""," | "&Aux!D3,"") & IF(Aux!E3<>""," | "&Aux!E3,"") & IF(Aux!F3<>""," | "&Aux!F3,"") & IF(Aux!G3<>""," | "&Aux!G3,"") & IF(Aux!H3<>""," | "&Aux!H3,"") & IF(Aux!I3<>""," | "&Aux!I3,"") & IF(Aux!J3<>""," | "&Aux!J3,"") & IF(Aux!K3<>""," | "&Aux!K3,"") & IF(Aux!L3<>""," | "&Aux!L3,"") & IF(Aux!M3<>""," | "&Aux!M3,"") & IF(B6>12," | (+"&(B6-12)&" más)",""))
A7: BAJO ELÉCTRICO | B7: =COUNTIFS(Registro!$D$2:$D$501,A7,Registro!$Q$2:$Q$501,"Disponible") -> 0 | C7: =IF(B7=0,"Sin vacantes",Aux!B4 & IF(Aux!C4<>""," | "&Aux!C4,"") & IF(Aux!D4<>""," | "&Aux!D4,"") & IF(Aux!E4<>""," | "&Aux!E4,"") & IF(Aux!F4<>""," | "&Aux!F4,"") & IF(Aux!G4<>""," | "&Aux!G4,"") & IF(Aux!H4<>""," | "&Aux!H4,"") & IF(Aux!I4<>""," | "&Aux!I4,"") & IF(Aux!J4<>""," | "&Aux!J4,"") & IF(Aux!K4<>""," | "&Aux!K4,"") & IF(Aux!L4<>""," | "&Aux!L4,"") & IF(Aux!M4<>""," | "&Aux!M4,"") & IF(B7>12," | (+"&(B7-12)&" más)",""))
A8: CANTO | B8: =COUNTIFS(Registro!$D$2:$D$501,A8,Registro!$Q$2:$Q$501,"Disponible") -> 0 | C8: =IF(B8=0,"Sin vacantes",Aux!B5 & IF(Aux!C5<>""," | "&Aux!C5,"") & IF(Aux!D5<>""," | "&Aux!D5,"") & IF(Aux!E5<>""," | "&Aux!E5,"") & IF(Aux!F5<>""," | "&Aux!F5,"") & IF(Aux!G5<>""," | "&Aux!G5,"") & IF(Aux!H5<>""," | "&Aux!H5,"") & IF(Aux!I5<>""," | "&Aux!I5,"") & IF(Aux!J5<>""," | "&Aux!J5,"") & IF(Aux!K5<>""," | "&Aux!K5,"") & IF(Aux!L5<>""," | "&Aux!L5,"") & IF(Aux!M5<>""," | "&Aux!M5,"") & IF(B8>12," | (+"&(B8-12)&" más)",""))
A9: CANTO VALENCIANO | B9: =COUNTIFS(Registro!$D$2:$D$501,A9,Registro!$Q$2:$Q$501,"Disponible") -> 0 | C9: =IF(B9=0,"Sin vacantes",Aux!B6 & IF(Aux!C6<>""," | "&Aux!C6,"") & IF(Aux!D6<>""," | "&Aux!D6,"") & IF(Aux!E6<>""," | "&Aux!E6,"") & IF(Aux!F6<>""," | "&Aux!F6,"") & IF(Aux!G6<>""," | "&Aux!G6,"") & IF(Aux!H6<>""," | "&Aux!H6,"") & IF(Aux!I6<>""," | "&Aux!I6,"") & IF(Aux!J6<>""," | "&Aux!J6,"") & IF(Aux!K6<>""," | "&Aux!K6,"") & IF(Aux!L6<>""," | "&Aux!L6,"") & IF(Aux!M6<>""," | "&Aux!M6,"") & IF(B9>12," | (+"&(B9-12)&" más)",""))
A10: CLARINETE | B10: =COUNTIFS(Registro!$D$2:$D$501,A10,Registro!$Q$2:$Q$501,"Disponible") -> 0 | C10: =IF(B10=0,"Sin vacantes",Aux!B7 & IF(Aux!C7<>""," | "&Aux!C7,"") & IF(Aux!D7<>""," | "&Aux!D7,"") & IF(Aux!E7<>""," | "&Aux!E7,"") & IF(Aux!F7<>""," | "&Aux!F7,"") & IF(Aux!G7<>""," | "&Aux!G7,"") & IF(Aux!H7<>""," | "&Aux!H7,"") & IF(Aux!I7<>""," | "&Aux!I7,"") & IF(Aux!J7<>""," | "&Aux!J7,"") & IF(Aux!K7<>""," | "&Aux!K7,"") & IF(Aux!L7<>""," | "&Aux!L7,"") & IF(Aux!M7<>""," | "&Aux!M7,"") & IF(B10>12," | (+"&(B10-12)&" más)",""))
A11: CLAVICÉMBALO | B11: =COUNTIFS(Registro!$D$2:$D$501,A11,Registro!$Q$2:$Q$501,"Disponible") -> 0 | C11: =IF(B11=0,"Sin vacantes",Aux!B8 & IF(Aux!C8<>""," | "&Aux!C8,"") & IF(Aux!D8<>""," | "&Aux!D8,"") & IF(Aux!E8<>""," | "&Aux!E8,"") & IF(Aux!F8<>""," | "&Aux!F8,"") & IF(Aux!G8<>""," | "&Aux!G8,"") & IF(Aux!H8<>""," | "&Aux!H8,"") & IF(Aux!I8<>""," | "&Aux!I8,"") & IF(Aux!J8<>""," | "&Aux!J8,"") & IF(Aux!K8<>""," | "&Aux!K8,"") & IF(Aux!L8<>""," | "&Aux!L8,"") & IF(Aux!M8<>""," | "&Aux!M8,"") & IF(B11>12," | (+"&(B11-12)&" más)",""))
A12: CONTRABAJO | B12: =COUNTIFS(Registro!$D$2:$D$501,A12,Registro!$Q$2:$Q$501,"Disponible") -> 0 | C12: =IF(B12=0,"Sin vacantes",Aux!B9 & IF(Aux!C9<>""," | "&Aux!C9,"") & IF(Aux!D9<>""," | "&Aux!D9,"") & IF(Aux!E9<>""," | "&Aux!E9,"") & IF(Aux!F9<>""," | "&Aux!F9,"") & IF(Aux!G9<>""," | "&Aux!G9,"") & IF(Aux!H9<>""," | "&Aux!H9,"") & IF(Aux!I9<>""," | "&Aux!I9,"") & IF(Aux!J9<>""," | "&Aux!J9,"") & IF(Aux!K9<>""," | "&Aux!K9,"") & IF(Aux!L9<>""," | "&Aux!L9,"") & IF(Aux!M9<>""," | "&Aux!M9,"") & IF(B12>12," | (+"&(B12-12)&" más)",""))
A13: DOLÇAINA | B13: =COUNTIFS(Registro!$D$2:$D$501,A13,Registro!$Q$2:$Q$501,"Disponible") -> 0 | C13: =IF(B13=0,"Sin vacantes",Aux!B10 & IF(Aux!C10<>""," | "&Aux!C10,"") & IF(Aux!D10<>""," | "&Aux!D10,"") & IF(Aux!E10<>""," | "&Aux!E10,"") & IF(Aux!F10<>""," | "&Aux!F10,"") & IF(Aux!G10<>""," | "&Aux!G10,"") & IF(Aux!H10<>""," | "&Aux!H10,"") & IF(Aux!I10<>""," | "&Aux!I10,"") & IF(Aux!J10<>""," | "&Aux!J10,"") & IF(Aux!K10<>""," | "&Aux!K10,"") & IF(Aux!L10<>""," | "&Aux!L10,"") & IF(Aux!M10<>""," | "&Aux!M10,"") & IF(B13>12," | (+"&(B13-12)&" más)",""))
A14: FAGOT | B14: =COUNTIFS(Registro!$D$2:$D$501,A14,Registro!$Q$2:$Q$501,"Disponible") -> 0 | C14: =IF(B14=0,"Sin vacantes",Aux!B11 & IF(Aux!C11<>""," | "&Aux!C11,"") & IF(Aux!D11<>""," | "&Aux!D11,"") & IF(Aux!E11<>""," | "&Aux!E11,"") & IF(Aux!F11<>""," | "&Aux!F11,"") & IF(Aux!G11<>""," | "&Aux!G11,"") & IF(Aux!H11<>""," | "&Aux!H11,"") & IF(Aux!I11<>""," | "&Aux!I11,"") & IF(Aux!J11<>""," | "&Aux!J11,"") & IF(Aux!K11<>""," | "&Aux!K11,"") & IF(Aux!L11<>""," | "&Aux!L11,"") & IF(Aux!M11<>""," | "&Aux!M11,"") & IF(B14>12," | (+"&(B14-12)&" más)",""))
A15: FLAUTA DE PICO | B15: =COUNTIFS(Registro!$D$2:$D$501,A15,Registro!$Q$2:$Q$501,"Disponible") -> 0 | C15: =IF(B15=0,"Sin vacantes",Aux!B12 & IF(Aux!C12<>""," | "&Aux!C12,"") & IF(Aux!D12<>""," | "&Aux!D12,"") & IF(Aux!E12<>""," | "&Aux!E12,"") & IF(Aux!F12<>""," | "&Aux!F12,"") & IF(Aux!G12<>""," | "&Aux!G12,"") & IF(Aux!H12<>""," | "&Aux!H12,"") & IF(Aux!I12<>""," | "&Aux!I12,"") & IF(Aux!J12<>""," | "&Aux!J12,"") & IF(Aux!K12<>""," | "&Aux!K12,"") & IF(Aux!L12<>""," | "&Aux!L12,"") & IF(Aux!M12<>""," | "&Aux!M12,"") & IF(B15>12," | (+"&(B15-12)&" más)",""))
A16: FLAUTA TRAVERSA | B16: =COUNTIFS(Registro!$D$2:$D$501,A16,Registro!$Q$2:$Q$501,"Disponible") -> 0 | C16: =IF(B16=0,"Sin vacantes",Aux!B13 & IF(Aux!C13<>""," | "&Aux!C13,"") & IF(Aux!D13<>""," | "&Aux!D13,"") & IF(Aux!E13<>""," | "&Aux!E13,"") & IF(Aux!F13<>""," | "&Aux!F13,"") & IF(Aux!G13<>""," | "&Aux!G13,"") & IF(Aux!H13<>""," | "&Aux!H13,"") & IF(Aux!I13<>""," | "&Aux!I13,"") & IF(Aux!J13<>""," | "&Aux!J13,"") & IF(Aux!K13<>""," | "&Aux!K13,"") & IF(Aux!L13<>""," | "&Aux!L13,"") & IF(Aux!M13<>""," | "&Aux!M13,"") & IF(B16>12," | (+"&(B16-12)&" más)",""))
... A33: VIOLONCHELO | B33: =COUNTIFS(Registro!$D$2:$D$501,A33,Registro!$Q$2:$Q$501,"Disponible") -> 0 | C33: =IF(B33=0,"Sin vacantes",Aux!B30 & IF(Aux!C30<>""," | "&Aux!C30,"") & IF(Aux!D30<>""," | "&Aux!D30,"") & IF(Aux!E30<>""," | "&Aux!E30,"") & IF(Aux!F30<>""," | "&Aux!F30,"") & IF(Aux!G30<>""," | "&Aux!G30,"") & IF(Aux!H30<>""," | "&Aux!H30,"") & IF(Aux!I30<>""," | "&Aux!I30,"") & IF(Aux!J30<>""," | "&Aux!J30,"") & IF(Aux!K30<>""," | "&Aux!K30,"") & IF(Aux!L30<>""," | "&Aux!L30,"") & IF(Aux!M30<>""," | "&Aux!M30,"") & IF(B33>12," | (+"&(B33-12)&" más)",""))
A35: VACANTES UTILIZADAS COMO REFUERZO
A36: Total horas completas como refuerzo: | B36: =COUNTIFS(Registro!$O$2:$O$501,"Sí",Registro!$N$2:$N$501,"1 hora")
A37: Medias horas usadas como refuerzo: | B37: =COUNTIFS(Registro!$O$2:$O$501,"Sí",Registro!$N$2:$N$501,"30 minutos") -> 0
A38: RESUMEN GENERAL
A39: Total vacantes registradas: | B39: =COUNTA(Registro!$D$2:$D$501) -> 0
A40: Total vacantes disponibles: | B40: =COUNTIF(Registro!$Q$2:$Q$501,"Disponible") -> 0 | C40: =IF(SUM(B5:B33)=B40,"✓ cuadra","⚠ descuadre de "&(B40-SUM(B5:B33))&": hay vacantes cuya especialidad no está en la lista")
A41: Total vacantes en trámite: | B41: =COUNTIF(Registro!$Q$2:$Q$501,"En trámite") -> 0
A42: Total vacantes no disponibles: | B42: =COUNTIF(Registro!$Q$2:$Q$501,"No disponible") -> 0
A43: Filas incompletas en el Registro: | B43: =COUNTIF(Registro!$AD$2:$AD$501,"Falta*")
A44: QUIÉN PUEDE ESCRIBIR EN EL LIBRO
A45: Esta lista alimenta el desplegable «Introducido por» de las dos hojas de registro. Cambia los cargos o añade los que necesite tu centro: las dos últimas casillas están libres.
A46: Jefatura
A47: Secretaría
A48: Administración
B49: ← libre
B50: ← libre

Sheet Registro
A1: Nº de orden | B1: Fecha de Introducción | C1: Introducido por | D1: Especialidad | E1: Apellidos (deja la plaza) | F1: Nombre (deja la plaza) | G1: NIA (deja la plaza) | H1: Curso | I1: Motivo de Vacante | J1: Observaciones sobre Motivo | K1: Nombre del Docente | L1: Horario Original | M1: Nuevo Horario | N1: Duración | O1: ¿En uso como Refuerzo? | P1: Detalle del Refuerzo | Q1: Estado de la Vacante | R1: Vía de cobertura | S1: Apellidos (ocupa la plaza) | T1: Nombre (ocupa la plaza) | U1: NIA (ocupa la plaza) | V1: Observaciones Generales | W1: _VacSlot | X1: _VacKey | Y1: _VacStr | Z1: _RefSlot | AA1: _RefKey | AB1: _RefStr | AC1: _Faltas | AD1: Comprobación | AE1: _iBaja | AF1: _iDisp | AG1: _iRef | AH1: _iOcio | AI1: _DocSlot | AJ1: _DocKey | AK1: _Revisar
A2: =IF(D2<>"",ROW()-1,"") | M2: =IF(L2="","",L2) | W2: =IF(Q2="Disponible",COUNTIFS($D$2:D2,D2,$Q$2:Q2,"Disponible"),"") | X2: =IF(W2<>"",D2&"|"&W2,"") | Y2: =IF(X2<>"",IF(K2<>"",K2&" ("&M2&")",M2),"") | Z2: =IF(O2="Sí",COUNTIFS($D$2:D2,D2,$O$2:O2,"Sí"),"") | AA2: =IF(Z2<>"",D2&"|"&Z2,"") | AB2: =IF(AA2<>"",IF(K2<>"",K2&" ("&M2&")",M2),"") | AC2: =IF($B2="","fecha, ","")&IF($C2="","quién lo introduce, ","")&IF($I2="","motivo, ","")&IF($K2="","docente, ","")&IF($L2="","horario, ","")&IF($N2="","duración, ","")&IF($Q2="","estado, ","")&IF(AND($I2="Otros",$J2=""),"detalle del motivo, ","")&IF(AND($O2="Sí",$P2=""),"detalle del refuerzo, ","")&IF(AND(OR($I2="Renuncia (hasta 30 nov)",$I2="Baja (desde 1 dic)",$I2="Renuncia excepcional (art. 25.3)",$I2="Traslado de expediente"),OR($E2="",$F2="",$G2="")),"quién deja la plaza, ","")&IF(AND($Q2="No disponible",$R2=""),"vía de cobertura, ","")&IF(AND(OR($R2="Lista de espera · propio centro",$R2="Traslado de expediente",$R2="Lista de espera · otro centro"),OR($S2="",$T2="",$U2="")),"quién ocupa la plaza, ","") | AD2: =IF($D2="","",IF(AND(LEN($AC2)=0,LEN($AK2)=0),"Completa",IF(LEN($AC2)=0,"Revisar: "&LEFT($AK2,LEN($AK2)-2),"Falta: "&LEFT($AC2,LEN($AC2)-2)&IF(LEN($AK2)>0," · Revisar: "&LEFT($AK2,LEN($AK2)-2),"")))) | AE2: =IF(AND($D2<>"",OR($I2="Renuncia (hasta 30 nov)",$I2="Baja (desde 1 dic)",$I2="Renuncia excepcional (art. 25.3)",$I2="Traslado de expediente")),COUNTIF($AE$1:AE1,">0")+1,"") | AF2: =IF($Q2="Disponible",COUNTIF($AF$1:AF1,">0")+1,"") | AG2: =IF($O2="Sí",COUNTIF($AG$1:AG1,">0")+1,"") | AH2: =IF(AND($Q2="Disponible",$O2<>"Sí"),COUNTIF($AH$1:AH1,">0")+1,"") | AI2: =IF(AND($Q2="Disponible",$K2<>""),COUNTIFS($K$2:K2,K2,$Q$2:Q2,"Disponible"),"") | AJ2: =IF(AI2<>"",K2&"|"&AI2,"") | AK2: =IF(AND($Q2="No disponible",OR($R2="Lista de espera · propio centro",$R2="Traslado de expediente",$R2="Lista de espera · otro centro"),$O2="Sí"),"la plaza ya tiene alumno y sigue marcada como refuerzo, ","")&IF(AND($R2="Reconvertida en refuerzo",$O2<>"Sí"),"reconvertida en refuerzo pero sin marcar «En uso como refuerzo», ","")
A3: =IF(D3<>"",ROW()-1,"") | M3: =IF(L3="","",L3) | W3: =IF(Q3="Disponible",COUNTIFS($D$2:D3,D3,$Q$2:Q3,"Disponible"),"") | X3: =IF(W3<>"",D3&"|"&W3,"") | Y3: =IF(X3<>"",IF(K3<>"",K3&" ("&M3&")",M3),"") | Z3: =IF(O3="Sí",COUNTIFS($D$2:D3,D3,$O$2:O3,"Sí"),"") | AA3: =IF(Z3<>"",D3&"|"&Z3,"") | AB3: =IF(AA3<>"",IF(K3<>"",K3&" ("&M3&")",M3),"") | AC3: =IF($B3="","fecha, ","")&IF($C3="","quién lo introduce, ","")&IF($I3="","motivo, ","")&IF($K3="","docente, ","")&IF($L3="","horario, ","")&IF($N3="","duración, ","")&IF($Q3="","estado, ","")&IF(AND($I3="Otros",$J3=""),"detalle del motivo, ","")&IF(AND($O3="Sí",$P3=""),"detalle del refuerzo, ","")&IF(AND(OR($I3="Renuncia (hasta 30 nov)",$I3="Baja (desde 1 dic)",$I3="Renuncia excepcional (art. 25.3)",$I3="Traslado de expediente"),OR($E3="",$F3="",$G3="")),"quién deja la plaza, ","")&IF(AND($Q3="No disponible",$R3=""),"vía de cobertura, ","")&IF(AND(OR($R3="Lista de espera · propio centro",$R3="Traslado de expediente",$R3="Lista de espera · otro centro"),OR($S3="",$T3="",$U3="")),"quién ocupa la plaza, ","") | AD3: =IF($D3="","",IF(AND(LEN($AC3)=0,LEN($AK3)=0),"Completa",IF(LEN($AC3)=0,"Revisar: "&LEFT($AK3,LEN($AK3)-2),"Falta: "&LEFT($AC3,LEN($AC3)-2)&IF(LEN($AK3)>0," · Revisar: "&LEFT($AK3,LEN($AK3)-2),"")))) | AE3: =IF(AND($D3<>"",OR($I3="Renuncia (hasta 30 nov)",$I3="Baja (desde 1 dic)",$I3="Renuncia excepcional (art. 25.3)",$I3="Traslado de expediente")),COUNTIF($AE$1:AE2,">0")+1,"") | AF3: =IF($Q3="Disponible",COUNTIF($AF$1:AF2,">0")+1,"") | AG3: =IF($O3="Sí",COUNTIF($AG$1:AG2,">0")+1,"") | AH3: =IF(AND($Q3="Disponible",$O3<>"Sí"),COUNTIF($AH$1:AH2,">0")+1,"") | AI3: =IF(AND($Q3="Disponible",$K3<>""),COUNTIFS($K$2:K3,K3,$Q$2:Q3,"Disponible"),"") | AJ3: =IF(AI3<>"",K3&"|"&AI3,"") | AK3: =IF(AND($Q3="No disponible",OR($R3="Lista de espera · propio centro",$R3="Traslado de expediente",$R3="Lista de espera · otro centro"),$O3="Sí"),"la plaza ya tiene alumno y sigue marcada como refuerzo, ","")&IF(AND($R3="Reconvertida en refuerzo",$O3<>"Sí"),"reconvertida en refuerzo pero sin marcar «En uso como refuerzo», ","")
A4: =IF(D4<>"",ROW()-1,"") | M4: =IF(L4="","",L4) | W4: =IF(Q4="Disponible",COUNTIFS($D$2:D4,D4,$Q$2:Q4,"Disponible"),"") | X4: =IF(W4<>"",D4&"|"&W4,"") | Y4: =IF(X4<>"",IF(K4<>"",K4&" ("&M4&")",M4),"") | Z4: =IF(O4="Sí",COUNTIFS($D$2:D4,D4,$O$2:O4,"Sí"),"") | AA4: =IF(Z4<>"",D4&"|"&Z4,"") | AB4: =IF(AA4<>"",IF(K4<>"",K4&" ("&M4&")",M4),"") | AC4: =IF($B4="","fecha, ","")&IF($C4="","quién lo introduce, ","")&IF($I4="","motivo, ","")&IF($K4="","docente, ","")&IF($L4="","horario, ","")&IF($N4="","duración, ","")&IF($Q4="","estado, ","")&IF(AND($I4="Otros",$J4=""),"detalle del motivo, ","")&IF(AND($O4="Sí",$P4=""),"detalle del refuerzo, ","")&IF(AND(OR($I4="Renuncia (hasta 30 nov)",$I4="Baja (desde 1 dic)",$I4="Renuncia excepcional (art. 25.3)",$I4="Traslado de expediente"),OR($E4="",$F4="",$G4="")),"quién deja la plaza, ","")&IF(AND($Q4="No disponible",$R4=""),"vía de cobertura, ","")&IF(AND(OR($R4="Lista de espera · propio centro",$R4="Traslado de expediente",$R4="Lista de espera · otro centro"),OR($S4="",$T4="",$U4="")),"quién ocupa la plaza, ","") | AD4: =IF($D4="","",IF(AND(LEN($AC4)=0,LEN($AK4)=0),"Completa",IF(LEN($AC4)=0,"Revisar: "&LEFT($AK4,LEN($AK4)-2),"Falta: "&LEFT($AC4,LEN($AC4)-2)&IF(LEN($AK4)>0," · Revisar: "&LEFT($AK4,LEN($AK4)-2),"")))) | AE4: =IF(AND($D4<>"",OR($I4="Renuncia (hasta 30 nov)",$I4="Baja (desde 1 dic)",$I4="Renuncia excepcional (art. 25.3)",$I4="Traslado de expediente")),COUNTIF($AE$1:AE3,">0")+1,"") | AF4: =IF($Q4="Disponible",COUNTIF($AF$1:AF3,">0")+1,"") | AG4: =IF($O4="Sí",COUNTIF($AG$1:AG3,">0")+1,"") | AH4: =IF(AND($Q4="Disponible",$O4<>"Sí"),COUNTIF($AH$1:AH3,">0")+1,"") | AI4: =IF(AND($Q4="Disponible",$K4<>""),COUNTIFS($K$2:K4,K4,$Q$2:Q4,"Disponible"),"") | AJ4: =IF(AI4<>"",K4&"|"&AI4,"") | AK4: =IF(AND($Q4="No disponible",OR($R4="Lista de espera · propio centro",$R4="Traslado de expediente",$R4="Lista de espera · otro centro"),$O4="Sí"),"la plaza ya tiene alumno y sigue marcada como refuerzo, ","")&IF(AND($R4="Reconvertida en refuerzo",$O4<>"Sí"),"reconvertida en refuerzo pero sin marcar «En uso como refuerzo», ","")
A5: =IF(D5<>"",ROW()-1,"") | M5: =IF(L5="","",L5) | W5: =IF(Q5="Disponible",COUNTIFS($D$2:D5,D5,$Q$2:Q5,"Disponible"),"") | X5: =IF(W5<>"",D5&"|"&W5,"") | Y5: =IF(X5<>"",IF(K5<>"",K5&" ("&M5&")",M5),"") | Z5: =IF(O5="Sí",COUNTIFS($D$2:D5,D5,$O$2:O5,"Sí"),"") | AA5: =IF(Z5<>"",D5&"|"&Z5,"") | AB5: =IF(AA5<>"",IF(K5<>"",K5&" ("&M5&")",M5),"") | AC5: =IF($B5="","fecha, ","")&IF($C5="","quién lo introduce, ","")&IF($I5="","motivo, ","")&IF($K5="","docente, ","")&IF($L5="","horario, ","")&IF($N5="","duración, ","")&IF($Q5="","estado, ","")&IF(AND($I5="Otros",$J5=""),"detalle del motivo, ","")&IF(AND($O5="Sí",$P5=""),"detalle del refuerzo, ","")&IF(AND(OR($I5="Renuncia (hasta 30 nov)",$I5="Baja (desde 1 dic)",$I5="Renuncia excepcional (art. 25.3)",$I5="Traslado de expediente"),OR($E5="",$F5="",$G5="")),"quién deja la plaza, ","")&IF(AND($Q5="No disponible",$R5=""),"vía de cobertura, ","")&IF(AND(OR($R5="Lista de espera · propio centro",$R5="Traslado de expediente",$R5="Lista de espera · otro centro"),OR($S5="",$T5="",$U5="")),"quién ocupa la plaza, ","") | AD5: =IF($D5="","",IF(AND(LEN($AC5)=0,LEN($AK5)=0),"Completa",IF(LEN($AC5)=0,"Revisar: "&LEFT($AK5,LEN($AK5)-2),"Falta: "&LEFT($AC5,LEN($AC5)-2)&IF(LEN($AK5)>0," · Revisar: "&LEFT($AK5,LEN($AK5)-2),"")))) | AE5: =IF(AND($D5<>"",OR($I5="Renuncia (hasta 30 nov)",$I5="Baja (desde 1 dic)",$I5="Renuncia excepcional (art. 25.3)",$I5="Traslado de expediente")),COUNTIF($AE$1:AE4,">0")+1,"") | AF5: =IF($Q5="Disponible",COUNTIF($AF$1:AF4,">0")+1,"") | AG5: =IF($O5="Sí",COUNTIF($AG$1:AG4,">0")+1,"") | AH5: =IF(AND($Q5="Disponible",$O5<>"Sí"),COUNTIF($AH$1:AH4,">0")+1,"") | AI5: =IF(AND($Q5="Disponible",$K5<>""),COUNTIFS($K$2:K5,K5,$Q$2:Q5,"Disponible"),"") | AJ5: =IF(AI5<>"",K5&"|"&AI5,"") | AK5: =IF(AND($Q5="No disponible",OR($R5="Lista de espera · propio centro",$R5="Traslado de expediente",$R5="Lista de espera · otro centro"),$O5="Sí"),"la plaza ya tiene alumno y sigue marcada como refuerzo, ","")&IF(AND($R5="Reconvertida en refuerzo",$O5<>"Sí"),"reconvertida en refuerzo pero sin marcar «En uso como refuerzo», ","")
A6: =IF(D6<>"",ROW()-1,"") | M6: =IF(L6="","",L6) | W6: =IF(Q6="Disponible",COUNTIFS($D$2:D6,D6,$Q$2:Q6,"Disponible"),"") | X6: =IF(W6<>"",D6&"|"&W6,"") | Y6: =IF(X6<>"",IF(K6<>"",K6&" ("&M6&")",M6),"") | Z6: =IF(O6="Sí",COUNTIFS($D$2:D6,D6,$O$2:O6,"Sí"),"") | AA6: =IF(Z6<>"",D6&"|"&Z6,"") | AB6: =IF(AA6<>"",IF(K6<>"",K6&" ("&M6&")",M6),"") | AC6: =IF($B6="","fecha, ","")&IF($C6="","quién lo introduce, ","")&IF($I6="","motivo, ","")&IF($K6="","docente, ","")&IF($L6="","horario, ","")&IF($N6="","duración, ","")&IF($Q6="","estado, ","")&IF(AND($I6="Otros",$J6=""),"detalle del motivo, ","")&IF(AND($O6="Sí",$P6=""),"detalle del refuerzo, ","")&IF(AND(OR($I6="Renuncia (hasta 30 nov)",$I6="Baja (desde 1 dic)",$I6="Renuncia excepcional (art. 25.3)",$I6="Traslado de expediente"),OR($E6="",$F6="",$G6="")),"quién deja la plaza, ","")&IF(AND($Q6="No disponible",$R6=""),"vía de cobertura, ","")&IF(AND(OR($R6="Lista de espera · propio centro",$R6="Traslado de expediente",$R6="Lista de espera · otro centro"),OR($S6="",$T6="",$U6="")),"quién ocupa la plaza, ","") | AD6: =IF($D6="","",IF(AND(LEN($AC6)=0,LEN($AK6)=0),"Completa",IF(LEN($AC6)=0,"Revisar: "&LEFT($AK6,LEN($AK6)-2),"Falta: "&LEFT($AC6,LEN($AC6)-2)&IF(LEN($AK6)>0," · Revisar: "&LEFT($AK6,LEN($AK6)-2),"")))) | AE6: =IF(AND($D6<>"",OR($I6="Renuncia (hasta 30 nov)",$I6="Baja (desde 1 dic)",$I6="Renuncia excepcional (art. 25.3)",$I6="Traslado de expediente")),COUNTIF($AE$1:AE5,">0")+1,"") | AF6: =IF($Q6="Disponible",COUNTIF($AF$1:AF5,">0")+1,"") | AG6: =IF($O6="Sí",COUNTIF($AG$1:AG5,">0")+1,"") | AH6: =IF(AND($Q6="Disponible",$O6<>"Sí"),COUNTIF($AH$1:AH5,">0")+1,"") | AI6: =IF(AND($Q6="Disponible",$K6<>""),COUNTIFS($K$2:K6,K6,$Q$2:Q6,"Disponible"),"") | AJ6: =IF(AI6<>"",K6&"|"&AI6,"") | AK6: =IF(AND($Q6="No disponible",OR($R6="Lista de espera · propio centro",$R6="Traslado de expediente",$R6="Lista de espera · otro centro"),$O6="Sí"),"la plaza ya tiene alumno y sigue marcada como refuerzo, ","")&IF(AND($R6="Reconvertida en refuerzo",$O6<>"Sí"),"reconvertida en refuerzo pero sin marcar «En uso como refuerzo», ","")
A7: =IF(D7<>"",ROW()-1,"") | M7: =IF(L7="","",L7) | W7: =IF(Q7="Disponible",COUNTIFS($D$2:D7,D7,$Q$2:Q7,"Disponible"),"") | X7: =IF(W7<>"",D7&"|"&W7,"") | Y7: =IF(X7<>"",IF(K7<>"",K7&" ("&M7&")",M7),"") | Z7: =IF(O7="Sí",COUNTIFS($D$2:D7,D7,$O$2:O7,"Sí"),"") | AA7: =IF(Z7<>"",D7&"|"&Z7,"") | AB7: =IF(AA7<>"",IF(K7<>"",K7&" ("&M7&")",M7),"") | AC7: =IF($B7="","fecha, ","")&IF($C7="","quién lo introduce, ","")&IF($I7="","motivo, ","")&IF($K7="","docente, ","")&IF($L7="","horario, ","")&IF($N7="","duración, ","")&IF($Q7="","estado, ","")&IF(AND($I7="Otros",$J7=""),"detalle del motivo, ","")&IF(AND($O7="Sí",$P7=""),"detalle del refuerzo, ","")&IF(AND(OR($I7="Renuncia (hasta 30 nov)",$I7="Baja (desde 1 dic)",$I7="Renuncia excepcional (art. 25.3)",$I7="Traslado de expediente"),OR($E7="",$F7="",$G7="")),"quién deja la plaza, ","")&IF(AND($Q7="No disponible",$R7=""),"vía de cobertura, ","")&IF(AND(OR($R7="Lista de espera · propio centro",$R7="Traslado de expediente",$R7="Lista de espera · otro centro"),OR($S7="",$T7="",$U7="")),"quién ocupa la plaza, ","") | AD7: =IF($D7="","",IF(AND(LEN($AC7)=0,LEN($AK7)=0),"Completa",IF(LEN($AC7)=0,"Revisar: "&LEFT($AK7,LEN($AK7)-2),"Falta: "&LEFT($AC7,LEN($AC7)-2)&IF(LEN($AK7)>0," · Revisar: "&LEFT($AK7,LEN($AK7)-2),"")))) | AE7: =IF(AND($D7<>"",OR($I7="Renuncia (hasta 30 nov)",$I7="Baja (desde 1 dic)",$I7="Renuncia excepcional (art. 25.3)",$I7="Traslado de expediente")),COUNTIF($AE$1:AE6,">0")+1,"") | AF7: =IF($Q7="Disponible",COUNTIF($AF$1:AF6,">0")+1,"") | AG7: =IF($O7="Sí",COUNTIF($AG$1:AG6,">0")+1,"") | AH7: =IF(AND($Q7="Disponible",$O7<>"Sí"),COUNTIF($AH$1:AH6,">0")+1,"") | AI7: =IF(AND($Q7="Disponible",$K7<>""),COUNTIFS($K$2:K7,K7,$Q$2:Q7,"Disponible"),"") | AJ7: =IF(AI7<>"",K7&"|"&AI7,"") | AK7: =IF(AND($Q7="No disponible",OR($R7="Lista de espera · propio centro",$R7="Traslado de expediente",$R7="Lista de espera · otro centro"),$O7="Sí"),"la plaza ya tiene alumno y sigue marcada como refuerzo, ","")&IF(AND($R7="Reconvertida en refuerzo",$O7<>"Sí"),"reconvertida en refuerzo pero sin marcar «En uso como refuerzo», ","")
A8: =IF(D8<>"",ROW()-1,"") | M8: =IF(L8="","",L8) | W8: =IF(Q8="Disponible",COUNTIFS($D$2:D8,D8,$Q$2:Q8,"Disponible"),"") | X8: =IF(W8<>"",D8&"|"&W8,"") | Y8: =IF(X8<>"",IF(K8<>"",K8&" ("&M8&")",M8),"") | Z8: =IF(O8="Sí",COUNTIFS($D$2:D8,D8,$O$2:O8,"Sí"),"") | AA8: =IF(Z8<>"",D8&"|"&Z8,"") | AB8: =IF(AA8<>"",IF(K8<>"",K8&" ("&M8&")",M8),"") | AC8: =IF($B8="","fecha, ","")&IF($C8="","quién lo introduce, ","")&IF($I8="","motivo, ","")&IF($K8="","docente, ","")&IF($L8="","horario, ","")&IF($N8="","duración, ","")&IF($Q8="","estado, ","")&IF(AND($I8="Otros",$J8=""),"detalle del motivo, ","")&IF(AND($O8="Sí",$P8=""),"detalle del refuerzo, ","")&IF(AND(OR($I8="Renuncia (hasta 30 nov)",$I8="Baja (desde 1 dic)",$I8="Renuncia excepcional (art. 25.3)",$I8="Traslado de expediente"),OR($E8="",$F8="",$G8="")),"quién deja la plaza, ","")&IF(AND($Q8="No disponible",$R8=""),"vía de cobertura, ","")&IF(AND(OR($R8="Lista de espera · propio centro",$R8="Traslado de expediente",$R8="Lista de espera · otro centro"),OR($S8="",$T8="",$U8="")),"quién ocupa la plaza, ","") | AD8: =IF($D8="","",IF(AND(LEN($AC8)=0,LEN($AK8)=0),"Completa",IF(LEN($AC8)=0,"Revisar: "&LEFT($AK8,LEN($AK8)-2),"Falta: "&LEFT($AC8,LEN($AC8)-2)&IF(LEN($AK8)>0," · Revisar: "&LEFT($AK8,LEN($AK8)-2),"")))) | AE8: =IF(AND($D8<>"",OR($I8="Renuncia (hasta 30 nov)",$I8="Baja (desde 1 dic)",$I8="Renuncia excepcional (art. 25.3)",$I8="Traslado de expediente")),COUNTIF($AE$1:AE7,">0")+1,"") | AF8: =IF($Q8="Disponible",COUNTIF($AF$1:AF7,">0")+1,"") | AG8: =IF($O8="Sí",COUNTIF($AG$1:AG7,">0")+1,"") | AH8: =IF(AND($Q8="Disponible",$O8<>"Sí"),COUNTIF($AH$1:AH7,">0")+1,"") | AI8: =IF(AND($Q8="Disponible",$K8<>""),COUNTIFS($K$2:K8,K8,$Q$2:Q8,"Disponible"),"") | AJ8: =IF(AI8<>"",K8&"|"&AI8,"") | AK8: =IF(AND($Q8="No disponible",OR($R8="Lista de espera · propio centro",$R8="Traslado de expediente",$R8="Lista de espera · otro centro"),$O8="Sí"),"la plaza ya tiene alumno y sigue marcada como refuerzo, ","")&IF(AND($R8="Reconvertida en refuerzo",$O8<>"Sí"),"reconvertida en refuerzo pero sin marcar «En uso como refuerzo», ","")
A9: =IF(D9<>"",ROW()-1,"") | M9: =IF(L9="","",L9) | W9: =IF(Q9="Disponible",COUNTIFS($D$2:D9,D9,$Q$2:Q9,"Disponible"),"") | X9: =IF(W9<>"",D9&"|"&W9,"") | Y9: =IF(X9<>"",IF(K9<>"",K9&" ("&M9&")",M9),"") | Z9: =IF(O9="Sí",COUNTIFS($D$2:D9,D9,$O$2:O9,"Sí"),"") | AA9: =IF(Z9<>"",D9&"|"&Z9,"") | AB9: =IF(AA9<>"",IF(K9<>"",K9&" ("&M9&")",M9),"") | AC9: =IF($B9="","fecha, ","")&IF($C9="","quién lo introduce, ","")&IF($I9="","motivo, ","")&IF($K9="","docente, ","")&IF($L9="","horario, ","")&IF($N9="","duración, ","")&IF($Q9="","estado, ","")&IF(AND($I9="Otros",$J9=""),"detalle del motivo, ","")&IF(AND($O9="Sí",$P9=""),"detalle del refuerzo, ","")&IF(AND(OR($I9="Renuncia (hasta 30 nov)",$I9="Baja (desde 1 dic)",$I9="Renuncia excepcional (art. 25.3)",$I9="Traslado de expediente"),OR($E9="",$F9="",$G9="")),"quién deja la plaza, ","")&IF(AND($Q9="No disponible",$R9=""),"vía de cobertura, ","")&IF(AND(OR($R9="Lista de espera · propio centro",$R9="Traslado de expediente",$R9="Lista de espera · otro centro"),OR($S9="",$T9="",$U9="")),"quién ocupa la plaza, ","") | AD9: =IF($D9="","",IF(AND(LEN($AC9)=0,LEN($AK9)=0),"Completa",IF(LEN($AC9)=0,"Revisar: "&LEFT($AK9,LEN($AK9)-2),"Falta: "&LEFT($AC9,LEN($AC9)-2)&IF(LEN($AK9)>0," · Revisar: "&LEFT($AK9,LEN($AK9)-2),"")))) | AE9: =IF(AND($D9<>"",OR($I9="Renuncia (hasta 30 nov)",$I9="Baja (desde 1 dic)",$I9="Renuncia excepcional (art. 25.3)",$I9="Traslado de expediente")),COUNTIF($AE$1:AE8,">0")+1,"") | AF9: =IF($Q9="Disponible",COUNTIF($AF$1:AF8,">0")+1,"") | AG9: =IF($O9="Sí",COUNTIF($AG$1:AG8,">0")+1,"") | AH9: =IF(AND($Q9="Disponible",$O9<>"Sí"),COUNTIF($AH$1:AH8,">0")+1,"") | AI9: =IF(AND($Q9="Disponible",$K9<>""),COUNTIFS($K$2:K9,K9,$Q$2:Q9,"Disponible"),"") | AJ9: =IF(AI9<>"",K9&"|"&AI9,"") | AK9: =IF(AND($Q9="No disponible",OR($R9="Lista de espera · propio centro",$R9="Traslado de expediente",$R9="Lista de espera · otro centro"),$O9="Sí"),"la plaza ya tiene alumno y sigue marcada como refuerzo, ","")&IF(AND($R9="Reconvertida en refuerzo",$O9<>"Sí"),"reconvertida en refuerzo pero sin marcar «En uso como refuerzo», ","")
A10: =IF(D10<>"",ROW()-1,"") | M10: =IF(L10="","",L10) | W10: =IF(Q10="Disponible",COUNTIFS($D$2:D10,D10,$Q$2:Q10,"Disponible"),"") | X10: =IF(W10<>"",D10&"|"&W10,"") | Y10: =IF(X10<>"",IF(K10<>"",K10&" ("&M10&")",M10),"") | Z10: =IF(O10="Sí",COUNTIFS($D$2:D10,D10,$O$2:O10,"Sí"),"") | AA10: =IF(Z10<>"",D10&"|"&Z10,"") | AB10: =IF(AA10<>"",IF(K10<>"",K10&" ("&M10&")",M10),"") | AC10: =IF($B10="","fecha, ","")&IF($C10="","quién lo introduce, ","")&IF($I10="","motivo, ","")&IF($K10="","docente, ","")&IF($L10="","horario, ","")&IF($N10="","duración, ","")&IF($Q10="","estado, ","")&IF(AND($I10="Otros",$J10=""),"detalle del motivo, ","")&IF(AND($O10="Sí",$P10=""),"detalle del refuerzo, ","")&IF(AND(OR($I10="Renuncia (hasta 30 nov)",$I10="Baja (desde 1 dic)",$I10="Renuncia excepcional (art. 25.3)",$I10="Traslado de expediente"),OR($E10="",$F10="",$G10="")),"quién deja la plaza, ","")&IF(AND($Q10="No disponible",$R10=""),"vía de cobertura, ","")&IF(AND(OR($R10="Lista de espera · propio centro",$R10="Traslado de expediente",$R10="Lista de espera · otro centro"),OR($S10="",$T10="",$U10="")),"quién ocupa la plaza, ","") | AD10: =IF($D10="","",IF(AND(LEN($AC10)=0,LEN($AK10)=0),"Completa",IF(LEN($AC10)=0,"Revisar: "&LEFT($AK10,LEN($AK10)-2),"Falta: "&LEFT($AC10,LEN($AC10)-2)&IF(LEN($AK10)>0," · Revisar: "&LEFT($AK10,LEN($AK10)-2),"")))) | AE10: =IF(AND($D10<>"",OR($I10="Renuncia (hasta 30 nov)",$I10="Baja (desde 1 dic)",$I10="Renuncia excepcional (art. 25.3)",$I10="Traslado de expediente")),COUNTIF($AE$1:AE9,">0")+1,"") | AF10: =IF($Q10="Disponible",COUNTIF($AF$1:AF9,">0")+1,"") | AG10: =IF($O10="Sí",COUNTIF($AG$1:AG9,">0")+1,"") | AH10: =IF(AND($Q10="Disponible",$O10<>"Sí"),COUNTIF($AH$1:AH9,">0")+1,"") | AI10: =IF(AND($Q10="Disponible",$K10<>""),COUNTIFS($K$2:K10,K10,$Q$2:Q10,"Disponible"),"") | AJ10: =IF(AI10<>"",K10&"|"&AI10,"") | AK10: =IF(AND($Q10="No disponible",OR($R10="Lista de espera · propio centro",$R10="Traslado de expediente",$R10="Lista de espera · otro centro"),$O10="Sí"),"la plaza ya tiene alumno y sigue marcada como refuerzo, ","")&IF(AND($R10="Reconvertida en refuerzo",$O10<>"Sí"),"reconvertida en refuerzo pero sin marcar «En uso como refuerzo», ","")
A11: =IF(D11<>"",ROW()-1,"") | M11: =IF(L11="","",L11) | W11: =IF(Q11="Disponible",COUNTIFS($D$2:D11,D11,$Q$2:Q11,"Disponible"),"") | X11: =IF(W11<>"",D11&"|"&W11,"") | Y11: =IF(X11<>"",IF(K11<>"",K11&" ("&M11&")",M11),"") | Z11: =IF(O11="Sí",COUNTIFS($D$2:D11,D11,$O$2:O11,"Sí"),"") | AA11: =IF(Z11<>"",D11&"|"&Z11,"") | AB11: =IF(AA11<>"",IF(K11<>"",K11&" ("&M11&")",M11),"") | AC11: =IF($B11="","fecha, ","")&IF($C11="","quién lo introduce, ","")&IF($I11="","motivo, ","")&IF($K11="","docente, ","")&IF($L11="","horario, ","")&IF($N11="","duración, ","")&IF($Q11="","estado, ","")&IF(AND($I11="Otros",$J11=""),"detalle del motivo, ","")&IF(AND($O11="Sí",$P11=""),"detalle del refuerzo, ","")&IF(AND(OR($I11="Renuncia (hasta 30 nov)",$I11="Baja (desde 1 dic)",$I11="Renuncia excepcional (art. 25.3)",$I11="Traslado de expediente"),OR($E11="",$F11="",$G11="")),"quién deja la plaza, ","")&IF(AND($Q11="No disponible",$R11=""),"vía de cobertura, ","")&IF(AND(OR($R11="Lista de espera · propio centro",$R11="Traslado de expediente",$R11="Lista de espera · otro centro"),OR($S11="",$T11="",$U11="")),"quién ocupa la plaza, ","") | AD11: =IF($D11="","",IF(AND(LEN($AC11)=0,LEN($AK11)=0),"Completa",IF(LEN($AC11)=0,"Revisar: "&LEFT($AK11,LEN($AK11)-2),"Falta: "&LEFT($AC11,LEN($AC11)-2)&IF(LEN($AK11)>0," · Revisar: "&LEFT($AK11,LEN($AK11)-2),"")))) | AE11: =IF(AND($D11<>"",OR($I11="Renuncia (hasta 30 nov)",$I11="Baja (desde 1 dic)",$I11="Renuncia excepcional (art. 25.3)",$I11="Traslado de expediente")),COUNTIF($AE$1:AE10,">0")+1,"") | AF11: =IF($Q11="Disponible",COUNTIF($AF$1:AF10,">0")+1,"") | AG11: =IF($O11="Sí",COUNTIF($AG$1:AG10,">0")+1,"") | AH11: =IF(AND($Q11="Disponible",$O11<>"Sí"),COUNTIF($AH$1:AH10,">0")+1,"") | AI11: =IF(AND($Q11="Disponible",$K11<>""),COUNTIFS($K$2:K11,K11,$Q$2:Q11,"Disponible"),"") | AJ11: =IF(AI11<>"",K11&"|"&AI11,"") | AK11: =IF(AND($Q11="No disponible",OR($R11="Lista de espera · propio centro",$R11="Traslado de expediente",$R11="Lista de espera · otro centro"),$O11="Sí"),"la plaza ya tiene alumno y sigue marcada como refuerzo, ","")&IF(AND($R11="Reconvertida en refuerzo",$O11<>"Sí"),"reconvertida en refuerzo pero sin marcar «En uso como refuerzo», ","")
A12: =IF(D12<>"",ROW()-1,"") | M12: =IF(L12="","",L12) | W12: =IF(Q12="Disponible",COUNTIFS($D$2:D12,D12,$Q$2:Q12,"Disponible"),"") | X12: =IF(W12<>"",D12&"|"&W12,"") | Y12: =IF(X12<>"",IF(K12<>"",K12&" ("&M12&")",M12),"") | Z12: =IF(O12="Sí",COUNTIFS($D$2:D12,D12,$O$2:O12,"Sí"),"") | AA12: =IF(Z12<>"",D12&"|"&Z12,"") | AB12: =IF(AA12<>"",IF(K12<>"",K12&" ("&M12&")",M12),"") | AC12: =IF($B12="","fecha, ","")&IF($C12="","quién lo introduce, ","")&IF($I12="","motivo, ","")&IF($K12="","docente, ","")&IF($L12="","horario, ","")&IF($N12="","duración, ","")&IF($Q12="","estado, ","")&IF(AND($I12="Otros",$J12=""),"detalle del motivo, ","")&IF(AND($O12="Sí",$P12=""),"detalle del refuerzo, ","")&IF(AND(OR($I12="Renuncia (hasta 30 nov)",$I12="Baja (desde 1 dic)",$I12="Renuncia excepcional (art. 25.3)",$I12="Traslado de expediente"),OR($E12="",$F12="",$G12="")),"quién deja la plaza, ","")&IF(AND($Q12="No disponible",$R12=""),"vía de cobertura, ","")&IF(AND(OR($R12="Lista de espera · propio centro",$R12="Traslado de expediente",$R12="Lista de espera · otro centro"),OR($S12="",$T12="",$U12="")),"quién ocupa la plaza, ","") | AD12: =IF($D12="","",IF(AND(LEN($AC12)=0,LEN($AK12)=0),"Completa",IF(LEN($AC12)=0,"Revisar: "&LEFT($AK12,LEN($AK12)-2),"Falta: "&LEFT($AC12,LEN($AC12)-2)&IF(LEN($AK12)>0," · Revisar: "&LEFT($AK12,LEN($AK12)-2),"")))) | AE12: =IF(AND($D12<>"",OR($I12="Renuncia (hasta 30 nov)",$I12="Baja (desde 1 dic)",$I12="Renuncia excepcional (art. 25.3)",$I12="Traslado de expediente")),COUNTIF($AE$1:AE11,">0")+1,"") | AF12: =IF($Q12="Disponible",COUNTIF($AF$1:AF11,">0")+1,"") | AG12: =IF($O12="Sí",COUNTIF($AG$1:AG11,">0")+1,"") | AH12: =IF(AND($Q12="Disponible",$O12<>"Sí"),COUNTIF($AH$1:AH11,">0")+1,"") | AI12: =IF(AND($Q12="Disponible",$K12<>""),COUNTIFS($K$2:K12,K12,$Q$2:Q12,"Disponible"),"") | AJ12: =IF(AI12<>"",K12&"|"&AI12,"") | AK12: =IF(AND($Q12="No disponible",OR($R12="Lista de espera · propio centro",$R12="Traslado de expediente",$R12="Lista de espera · otro centro"),$O12="Sí"),"la plaza ya tiene alumno y sigue marcada como refuerzo, ","")&IF(AND($R12="Reconvertida en refuerzo",$O12<>"Sí"),"reconvertida en refuerzo pero sin marcar «En uso como refuerzo», ","")
A13: =IF(D13<>"",ROW()-1,"") | M13: =IF(L13="","",L13) | W13: =IF(Q13="Disponible",COUNTIFS($D$2:D13,D13,$Q$2:Q13,"Disponible"),"") | X13: =IF(W13<>"",D13&"|"&W13,"") | Y13: =IF(X13<>"",IF(K13<>"",K13&" ("&M13&")",M13),"") | Z13: =IF(O13="Sí",COUNTIFS($D$2:D13,D13,$O$2:O13,"Sí"),"") | AA13: =IF(Z13<>"",D13&"|"&Z13,"") | AB13: =IF(AA13<>"",IF(K13<>"",K13&" ("&M13&")",M13),"") | AC13: =IF($B13="","fecha, ","")&IF($C13="","quién lo introduce, ","")&IF($I13="","motivo, ","")&IF($K13="","docente, ","")&IF($L13="","horario, ","")&IF($N13="","duración, ","")&IF($Q13="","estado, ","")&IF(AND($I13="Otros",$J13=""),"detalle del motivo, ","")&IF(AND($O13="Sí",$P13=""),"detalle del refuerzo, ","")&IF(AND(OR($I13="Renuncia (hasta 30 nov)",$I13="Baja (desde 1 dic)",$I13="Renuncia excepcional (art. 25.3)",$I13="Traslado de expediente"),OR($E13="",$F13="",$G13="")),"quién deja la plaza, ","")&IF(AND($Q13="No disponible",$R13=""),"vía de cobertura, ","")&IF(AND(OR($R13="Lista de espera · propio centro",$R13="Traslado de expediente",$R13="Lista de espera · otro centro"),OR($S13="",$T13="",$U13="")),"quién ocupa la plaza, ","") | AD13: =IF($D13="","",IF(AND(LEN($AC13)=0,LEN($AK13)=0),"Completa",IF(LEN($AC13)=0,"Revisar: "&LEFT($AK13,LEN($AK13)-2),"Falta: "&LEFT($AC13,LEN($AC13)-2)&IF(LEN($AK13)>0," · Revisar: "&LEFT($AK13,LEN($AK13)-2),"")))) | AE13: =IF(AND($D13<>"",OR($I13="Renuncia (hasta 30 nov)",$I13="Baja (desde 1 dic)",$I13="Renuncia excepcional (art. 25.3)",$I13="Traslado de expediente")),COUNTIF($AE$1:AE12,">0")+1,"") | AF13: =IF($Q13="Disponible",COUNTIF($AF$1:AF12,">0")+1,"") | AG13: =IF($O13="Sí",COUNTIF($AG$1:AG12,">0")+1,"") | AH13: =IF(AND($Q13="Disponible",$O13<>"Sí"),COUNTIF($AH$1:AH12,">0")+1,"") | AI13: =IF(AND($Q13="Disponible",$K13<>""),COUNTIFS($K$2:K13,K13,$Q$2:Q13,"Disponible"),"") | AJ13: =IF(AI13<>"",K13&"|"&AI13,"") | AK13: =IF(AND($Q13="No disponible",OR($R13="Lista de espera · propio centro",$R13="Traslado de expediente",$R13="Lista de espera · otro centro"),$O13="Sí"),"la plaza ya tiene alumno y sigue marcada como refuerzo, ","")&IF(AND($R13="Reconvertida en refuerzo",$O13<>"Sí"),"reconvertida en refuerzo pero sin marcar «En uso como refuerzo», ","")
... A501: =IF(D501<>"",ROW()-1,"") | M501: =IF(L501="","",L501) | W501: =IF(Q501="Disponible",COUNTIFS($D$2:D501,D501,$Q$2:Q501,"Disponible"),"") | X501: =IF(W501<>"",D501&"|"&W501,"") | Y501: =IF(X501<>"",IF(K501<>"",K501&" ("&M501&")",M501),"") | Z501: =IF(O501="Sí",COUNTIFS($D$2:D501,D501,$O$2:O501,"Sí"),"") | AA501: =IF(Z501<>"",D501&"|"&Z501,"") | AB501: =IF(AA501<>"",IF(K501<>"",K501&" ("&M501&")",M501),"") | AC501: =IF($B501="","fecha, ","")&IF($C501="","quién lo introduce, ","")&IF($I501="","motivo, ","")&IF($K501="","docente, ","")&IF($L501="","horario, ","")&IF($N501="","duración, ","")&IF($Q501="","estado, ","")&IF(AND($I501="Otros",$J501=""),"detalle del motivo, ","")&IF(AND($O501="Sí",$P501=""),"detalle del refuerzo, ","")&IF(AND(OR($I501="Renuncia (hasta 30 nov)",$I501="Baja (desde 1 dic)",$I501="Renuncia excepcional (art. 25.3)",$I501="Traslado de expediente"),OR($E501="",$F501="",$G501="")),"quién deja la plaza, ","")&IF(AND($Q501="No disponible",$R501=""),"vía de cobertura, ","")&IF(AND(OR($R501="Lista de espera · propio centro",$R501="Traslado de expediente",$R501="Lista de espera · otro centro"),OR($S501="",$T501="",$U501="")),"quién ocupa la plaza, ","") | AD501: =IF($D501="","",IF(AND(LEN($AC501)=0,LEN($AK501)=0),"Completa",IF(LEN($AC501)=0,"Revisar: "&LEFT($AK501,LEN($AK501)-2),"Falta: "&LEFT($AC501,LEN($AC501)-2)&IF(LEN($AK501)>0," · Revisar: "&LEFT($AK501,LEN($AK501)-2),"")))) | AE501: =IF(AND($D501<>"",OR($I501="Renuncia (hasta 30 nov)",$I501="Baja (desde 1 dic)",$I501="Renuncia excepcional (art. 25.3)",$I501="Traslado de expediente")),COUNTIF($AE$1:AE500,">0")+1,"") | AF501: =IF($Q501="Disponible",COUNTIF($AF$1:AF500,">0")+1,"") | AG501: =IF($O501="Sí",COUNTIF($AG$1:AG500,">0")+1,"") | AH501: =IF(AND($Q501="Disponible",$O501<>"Sí"),COUNTIF($AH$1:AH500,">0")+1,"") | AI501: =IF(AND($Q501="Disponible",$K501<>""),COUNTIFS($K$2:K501,K501,$Q$2:Q501,"Disponible"),"") | AJ501: =IF(AI501<>"",K501&"|"&AI501,"") | AK501: =IF(AND($Q501="No disponible",OR($R501="Lista de espera · propio centro",$R501="Traslado de expediente",$R501="Lista de espera · otro centro"),$O501="Sí"),"la plaza ya tiene alumno y sigue marcada como refuerzo, ","")&IF(AND($R501="Reconvertida en refuerzo",$O501<>"Sí"),"reconvertida en refuerzo pero sin marcar «En uso como refuerzo», ","")

Sheet Aux
A1: Especialidad | B1: Slot 1 | C1: Slot 2 | D1: Slot 3 | E1: Slot 4 | F1: Slot 5 | G1: Slot 6 | H1: Slot 7 | I1: Slot 8 | J1: Slot 9 | K1: Slot 10 | L1: Slot 11 | M1: Slot 12
A2: ACORDEÓN | B2: =IFERROR(INDEX(Registro!$Y$2:$Y$501,MATCH($A2&"|"&1,Registro!$X$2:$X$501,0)),"") | C2: =IFERROR(INDEX(Registro!$Y$2:$Y$501,MATCH($A2&"|"&2,Registro!$X$2:$X$501,0)),"") | D2: =IFERROR(INDEX(Registro!$Y$2:$Y$501,MATCH($A2&"|"&3,Registro!$X$2:$X$501,0)),"") | E2: =IFERROR(INDEX(Registro!$Y$2:$Y$501,MATCH($A2&"|"&4,Registro!$X$2:$X$501,0)),"") | F2: =IFERROR(INDEX(Registro!$Y$2:$Y$501,MATCH($A2&"|"&5,Registro!$X$2:$X$501,0)),"") | G2: =IFERROR(INDEX(Registro!$Y$2:$Y$501,MATCH($A2&"|"&6,Registro!$X$2:$X$501,0)),"") | H2: =IFERROR(INDEX(Registro!$Y$2:$Y$501,MATCH($A2&"|"&7,Registro!$X$2:$X$501,0)),"") | I2: =IFERROR(INDEX(Registro!$Y$2:$Y$501,MATCH($A2&"|"&8,Registro!$X$2:$X$501,0)),"") | J2: =IFERROR(INDEX(Registro!$Y$2:$Y$501,MATCH($A2&"|"&9,Registro!$X$2:$X$501,0)),"") | K2: =IFERROR(INDEX(Registro!$Y$2:$Y$501,MATCH($A2&"|"&10,Registro!$X$2:$X$501,0)),"") | L2: =IFERROR(INDEX(Registro!$Y$2:$Y$501,MATCH($A2&"|"&11,Registro!$X$2:$X$501,0)),"") | M2: =IFERROR(INDEX(Registro!$Y$2:$Y$501,MATCH($A2&"|"&12,Registro!$X$2:$X$501,0)),"")
A3: ARPA | B3: =IFERROR(INDEX(Registro!$Y$2:$Y$501,MATCH($A3&"|"&1,Registro!$X$2:$X$501,0)),"") | C3: =IFERROR(INDEX(Registro!$Y$2:$Y$501,MATCH($A3&"|"&2,Registro!$X$2:$X$501,0)),"") | D3: =IFERROR(INDEX(Registro!$Y$2:$Y$501,MATCH($A3&"|"&3,Registro!$X$2:$X$501,0)),"") | E3: =IFERROR(INDEX(Registro!$Y$2:$Y$501,MATCH($A3&"|"&4,Registro!$X$2:$X$501,0)),"") | F3: =IFERROR(INDEX(Registro!$Y$2:$Y$501,MATCH($A3&"|"&5,Registro!$X$2:$X$501,0)),"") | G3: =IFERROR(INDEX(Registro!$Y$2:$Y$501,MATCH($A3&"|"&6,Registro!$X$2:$X$501,0)),"") | H3: =IFERROR(INDEX(Registro!$Y$2:$Y$501,MATCH($A3&"|"&7,Registro!$X$2:$X$501,0)),"") | I3: =IFERROR(INDEX(Registro!$Y$2:$Y$501,MATCH($A3&"|"&8,Registro!$X$2:$X$501,0)),"") | J3: =IFERROR(INDEX(Registro!$Y$2:$Y$501,MATCH($A3&"|"&9,Registro!$X$2:$X$501,0)),"") | K3: =IFERROR(INDEX(Registro!$Y$2:$Y$501,MATCH($A3&"|"&10,Registro!$X$2:$X$501,0)),"") | L3: =IFERROR(INDEX(Registro!$Y$2:$Y$501,MATCH($A3&"|"&11,Registro!$X$2:$X$501,0)),"") | M3: =IFERROR(INDEX(Registro!$Y$2:$Y$501,MATCH($A3&"|"&12,Registro!$X$2:$X$501,0)),"")
A4: BAJO ELÉCTRICO | B4: =IFERROR(INDEX(Registro!$Y$2:$Y$501,MATCH($A4&"|"&1,Registro!$X$2:$X$501,0)),"") | C4: =IFERROR(INDEX(Registro!$Y$2:$Y$501,MATCH($A4&"|"&2,Registro!$X$2:$X$501,0)),"") | D4: =IFERROR(INDEX(Registro!$Y$2:$Y$501,MATCH($A4&"|"&3,Registro!$X$2:$X$501,0)),"") | E4: =IFERROR(INDEX(Registro!$Y$2:$Y$501,MATCH($A4&"|"&4,Registro!$X$2:$X$501,0)),"") | F4: =IFERROR(INDEX(Registro!$Y$2:$Y$501,MATCH($A4&"|"&5,Registro!$X$2:$X$501,0)),"") | G4: =IFERROR(INDEX(Registro!$Y$2:$Y$501,MATCH($A4&"|"&6,Registro!$X$2:$X$501,0)),"") | H4: =IFERROR(INDEX(Registro!$Y$2:$Y$501,MATCH($A4&"|"&7,Registro!$X$2:$X$501,0)),"") | I4: =IFERROR(INDEX(Registro!$Y$2:$Y$501,MATCH($A4&"|"&8,Registro!$X$2:$X$501,0)),"") | J4: =IFERROR(INDEX(Registro!$Y$2:$Y$501,MATCH($A4&"|"&9,Registro!$X$2:$X$501,0)),"") | K4: =IFERROR(INDEX(Registro!$Y$2:$Y$501,MATCH($A4&"|"&10,Registro!$X$2:$X$501,0)),"") | L4: =IFERROR(INDEX(Registro!$Y$2:$Y$501,MATCH($A4&"|"&11,Registro!$X$2:$X$501,0)),"") | M4: =IFERROR(INDEX(Registro!$Y$2:$Y$501,MATCH($A4&"|"&12,Registro!$X$2:$X$501,0)),"")
A5: CANTO | B5: =IFERROR(INDEX(Registro!$Y$2:$Y$501,MATCH($A5&"|"&1,Registro!$X$2:$X$501,0)),"") | C5: =IFERROR(INDEX(Registro!$Y$2:$Y$501,MATCH($A5&"|"&2,Registro!$X$2:$X$501,0)),"") | D5: =IFERROR(INDEX(Registro!$Y$2:$Y$501,MATCH($A5&"|"&3,Registro!$X$2:$X$501,0)),"") | E5: =IFERROR(INDEX(Registro!$Y$2:$Y$501,MATCH($A5&"|"&4,Registro!$X$2:$X$501,0)),"") | F5: =IFERROR(INDEX(Registro!$Y$2:$Y$501,MATCH($A5&"|"&5,Registro!$X$2:$X$501,0)),"") | G5: =IFERROR(INDEX(Registro!$Y$2:$Y$501,MATCH($A5&"|"&6,Registro!$X$2:$X$501,0)),"") | H5: =IFERROR(INDEX(Registro!$Y$2:$Y$501,MATCH($A5&"|"&7,Registro!$X$2:$X$501,0)),"") | I5: =IFERROR(INDEX(Registro!$Y$2:$Y$501,MATCH($A5&"|"&8,Registro!$X$2:$X$501,0)),"") | J5: =IFERROR(INDEX(Registro!$Y$2:$Y$501,MATCH($A5&"|"&9,Registro!$X$2:$X$501,0)),"") | K5: =IFERROR(INDEX(Registro!$Y$2:$Y$501,MATCH($A5&"|"&10,Registro!$X$2:$X$501,0)),"") | L5: =IFERROR(INDEX(Registro!$Y$2:$Y$501,MATCH($A5&"|"&11,Registro!$X$2:$X$501,0)),"") | M5: =IFERROR(INDEX(Registro!$Y$2:$Y$501,MATCH($A5&"|"&12,Registro!$X$2:$X$501,0)),"")
A6: CANTO VALENCIANO | B6: =IFERROR(INDEX(Registro!$Y$2:$Y$501,MATCH($A6&"|"&1,Registro!$X$2:$X$501,0)),"") | C6: =IFERROR(INDEX(Registro!$Y$2:$Y$501,MATCH($A6&"|"&2,Registro!$X$2:$X$501,0)),"") | D6: =IFERROR(INDEX(Registro!$Y$2:$Y$501,MATCH($A6&"|"&3,Registro!$X$2:$X$501,0)),"") | E6: =IFERROR(INDEX(Registro!$Y$2:$Y$501,MATCH($A6&"|"&4,Registro!$X$2:$X$501,0)),"") | F6: =IFERROR(INDEX(Registro!$Y$2:$Y$501,MATCH($A6&"|"&5,Registro!$X$2:$X$501,0)),"") | G6: =IFERROR(INDEX(Registro!$Y$2:$Y$501,MATCH($A6&"|"&6,Registro!$X$2:$X$501,0)),"") | H6: =IFERROR(INDEX(Registro!$Y$2:$Y$501,MATCH($A6&"|"&7,Registro!$X$2:$X$501,0)),"") | I6: =IFERROR(INDEX(Registro!$Y$2:$Y$501,MATCH($A6&"|"&8,Registro!$X$2:$X$501,0)),"") | J6: =IFERROR(INDEX(Registro!$Y$2:$Y$501,MATCH($A6&"|"&9,Registro!$X$2:$X$501,0)),"") | K6: =IFERROR(INDEX(Registro!$Y$2:$Y$501,MATCH($A6&"|"&10,Registro!$X$2:$X$501,0)),"") | L6: =IFERROR(INDEX(Registro!$Y$2:$Y$501,MATCH($A6&"|"&11,Registro!$X$2:$X$501,0)),"") | M6: =IFERROR(INDEX(Registro!$Y$2:$Y$501,MATCH($A6&"|"&12,Registro!$X$2:$X$501,0)),"")
A7: CLARINETE | B7: =IFERROR(INDEX(Registro!$Y$2:$Y$501,MATCH($A7&"|"&1,Registro!$X$2:$X$501,0)),"") | C7: =IFERROR(INDEX(Registro!$Y$2:$Y$501,MATCH($A7&"|"&2,Registro!$X$2:$X$501,0)),"") | D7: =IFERROR(INDEX(Registro!$Y$2:$Y$501,MATCH($A7&"|"&3,Registro!$X$2:$X$501,0)),"") | E7: =IFERROR(INDEX(Registro!$Y$2:$Y$501,MATCH($A7&"|"&4,Registro!$X$2:$X$501,0)),"") | F7: =IFERROR(INDEX(Registro!$Y$2:$Y$501,MATCH($A7&"|"&5,Registro!$X$2:$X$501,0)),"") | G7: =IFERROR(INDEX(Registro!$Y$2:$Y$501,MATCH($A7&"|"&6,Registro!$X$2:$X$501,0)),"") | H7: =IFERROR(INDEX(Registro!$Y$2:$Y$501,MATCH($A7&"|"&7,Registro!$X$2:$X$501,0)),"") | I7: =IFERROR(INDEX(Registro!$Y$2:$Y$501,MATCH($A7&"|"&8,Registro!$X$2:$X$501,0)),"") | J7: =IFERROR(INDEX(Registro!$Y$2:$Y$501,MATCH($A7&"|"&9,Registro!$X$2:$X$501,0)),"") | K7: =IFERROR(INDEX(Registro!$Y$2:$Y$501,MATCH($A7&"|"&10,Registro!$X$2:$X$501,0)),"") | L7: =IFERROR(INDEX(Registro!$Y$2:$Y$501,MATCH($A7&"|"&11,Registro!$X$2:$X$501,0)),"") | M7: =IFERROR(INDEX(Registro!$Y$2:$Y$501,MATCH($A7&"|"&12,Registro!$X$2:$X$501,0)),"")
A8: CLAVICÉMBALO | B8: =IFERROR(INDEX(Registro!$Y$2:$Y$501,MATCH($A8&"|"&1,Registro!$X$2:$X$501,0)),"") | C8: =IFERROR(INDEX(Registro!$Y$2:$Y$501,MATCH($A8&"|"&2,Registro!$X$2:$X$501,0)),"") | D8: =IFERROR(INDEX(Registro!$Y$2:$Y$501,MATCH($A8&"|"&3,Registro!$X$2:$X$501,0)),"") | E8: =IFERROR(INDEX(Registro!$Y$2:$Y$501,MATCH($A8&"|"&4,Registro!$X$2:$X$501,0)),"") | F8: =IFERROR(INDEX(Registro!$Y$2:$Y$501,MATCH($A8&"|"&5,Registro!$X$2:$X$501,0)),"") | G8: =IFERROR(INDEX(Registro!$Y$2:$Y$501,MATCH($A8&"|"&6,Registro!$X$2:$X$501,0)),"") | H8: =IFERROR(INDEX(Registro!$Y$2:$Y$501,MATCH($A8&"|"&7,Registro!$X$2:$X$501,0)),"") | I8: =IFERROR(INDEX(Registro!$Y$2:$Y$501,MATCH($A8&"|"&8,Registro!$X$2:$X$501,0)),"") | J8: =IFERROR(INDEX(Registro!$Y$2:$Y$501,MATCH($A8&"|"&9,Registro!$X$2:$X$501,0)),"") | K8: =IFERROR(INDEX(Registro!$Y$2:$Y$501,MATCH($A8&"|"&10,Registro!$X$2:$X$501,0)),"") | L8: =IFERROR(INDEX(Registro!$Y$2:$Y$501,MATCH($A8&"|"&11,Registro!$X$2:$X$501,0)),"") | M8: =IFERROR(INDEX(Registro!$Y$2:$Y$501,MATCH($A8&"|"&12,Registro!$X$2:$X$501,0)),"")
A9: CONTRABAJO | B9: =IFERROR(INDEX(Registro!$Y$2:$Y$501,MATCH($A9&"|"&1,Registro!$X$2:$X$501,0)),"") | C9: =IFERROR(INDEX(Registro!$Y$2:$Y$501,MATCH($A9&"|"&2,Registro!$X$2:$X$501,0)),"") | D9: =IFERROR(INDEX(Registro!$Y$2:$Y$501,MATCH($A9&"|"&3,Registro!$X$2:$X$501,0)),"") | E9: =IFERROR(INDEX(Registro!$Y$2:$Y$501,MATCH($A9&"|"&4,Registro!$X$2:$X$501,0)),"") | F9: =IFERROR(INDEX(Registro!$Y$2:$Y$501,MATCH($A9&"|"&5,Registro!$X$2:$X$501,0)),"") | G9: =IFERROR(INDEX(Registro!$Y$2:$Y$501,MATCH($A9&"|"&6,Registro!$X$2:$X$501,0)),"") | H9: =IFERROR(INDEX(Registro!$Y$2:$Y$501,MATCH($A9&"|"&7,Registro!$X$2:$X$501,0)),"") | I9: =IFERROR(INDEX(Registro!$Y$2:$Y$501,MATCH($A9&"|"&8,Registro!$X$2:$X$501,0)),"") | J9: =IFERROR(INDEX(Registro!$Y$2:$Y$501,MATCH($A9&"|"&9,Registro!$X$2:$X$501,0)),"") | K9: =IFERROR(INDEX(Registro!$Y$2:$Y$501,MATCH($A9&"|"&10,Registro!$X$2:$X$501,0)),"") | L9: =IFERROR(INDEX(Registro!$Y$2:$Y$501,MATCH($A9&"|"&11,Registro!$X$2:$X$501,0)),"") | M9: =IFERROR(INDEX(Registro!$Y$2:$Y$501,MATCH($A9&"|"&12,Registro!$X$2:$X$501,0)),"")
A10: DOLÇAINA | B10: =IFERROR(INDEX(Registro!$Y$2:$Y$501,MATCH($A10&"|"&1,Registro!$X$2:$X$501,0)),"") | C10: =IFERROR(INDEX(Registro!$Y$2:$Y$501,MATCH($A10&"|"&2,Registro!$X$2:$X$501,0)),"") | D10: =IFERROR(INDEX(Registro!$Y$2:$Y$501,MATCH($A10&"|"&3,Registro!$X$2:$X$501,0)),"") | E10: =IFERROR(INDEX(Registro!$Y$2:$Y$501,MATCH($A10&"|"&4,Registro!$X$2:$X$501,0)),"") | F10: =IFERROR(INDEX(Registro!$Y$2:$Y$501,MATCH($A10&"|"&5,Registro!$X$2:$X$501,0)),"") | G10: =IFERROR(INDEX(Registro!$Y$2:$Y$501,MATCH($A10&"|"&6,Registro!$X$2:$X$501,0)),"") | H10: =IFERROR(INDEX(Registro!$Y$2:$Y$501,MATCH($A10&"|"&7,Registro!$X$2:$X$501,0)),"") | I10: =IFERROR(INDEX(Registro!$Y$2:$Y$501,MATCH($A10&"|"&8,Registro!$X$2:$X$501,0)),"") | J10: =IFERROR(INDEX(Registro!$Y$2:$Y$501,MATCH($A10&"|"&9,Registro!$X$2:$X$501,0)),"") | K10: =IFERROR(INDEX(Registro!$Y$2:$Y$501,MATCH($A10&"|"&10,Registro!$X$2:$X$501,0)),"") | L10: =IFERROR(INDEX(Registro!$Y$2:$Y$501,MATCH($A10&"|"&11,Registro!$X$2:$X$501,0)),"") | M10: =IFERROR(INDEX(Registro!$Y$2:$Y$501,MATCH($A10&"|"&12,Registro!$X$2:$X$501,0)),"")
A11: FAGOT | B11: =IFERROR(INDEX(Registro!$Y$2:$Y$501,MATCH($A11&"|"&1,Registro!$X$2:$X$501,0)),"") | C11: =IFERROR(INDEX(Registro!$Y$2:$Y$501,MATCH($A11&"|"&2,Registro!$X$2:$X$501,0)),"") | D11: =IFERROR(INDEX(Registro!$Y$2:$Y$501,MATCH($A11&"|"&3,Registro!$X$2:$X$501,0)),"") | E11: =IFERROR(INDEX(Registro!$Y$2:$Y$501,MATCH($A11&"|"&4,Registro!$X$2:$X$501,0)),"") | F11: =IFERROR(INDEX(Registro!$Y$2:$Y$501,MATCH($A11&"|"&5,Registro!$X$2:$X$501,0)),"") | G11: =IFERROR(INDEX(Registro!$Y$2:$Y$501,MATCH($A11&"|"&6,Registro!$X$2:$X$501,0)),"") | H11: =IFERROR(INDEX(Registro!$Y$2:$Y$501,MATCH($A11&"|"&7,Registro!$X$2:$X$501,0)),"") | I11: =IFERROR(INDEX(Registro!$Y$2:$Y$501,MATCH($A11&"|"&8,Registro!$X$2:$X$501,0)),"") | J11: =IFERROR(INDEX(Registro!$Y$2:$Y$501,MATCH($A11&"|"&9,Registro!$X$2:$X$501,0)),"") | K11: =IFERROR(INDEX(Registro!$Y$2:$Y$501,MATCH($A11&"|"&10,Registro!$X$2:$X$501,0)),"") | L11: =IFERROR(INDEX(Registro!$Y$2:$Y$501,MATCH($A11&"|"&11,Registro!$X$2:$X$501,0)),"") | M11: =IFERROR(INDEX(Registro!$Y$2:$Y$501,MATCH($A11&"|"&12,Registro!$X$2:$X$501,0)),"")
A12: FLAUTA DE PICO | B12: =IFERROR(INDEX(Registro!$Y$2:$Y$501,MATCH($A12&"|"&1,Registro!$X$2:$X$501,0)),"") | C12: =IFERROR(INDEX(Registro!$Y$2:$Y$501,MATCH($A12&"|"&2,Registro!$X$2:$X$501,0)),"") | D12: =IFERROR(INDEX(Registro!$Y$2:$Y$501,MATCH($A12&"|"&3,Registro!$X$2:$X$501,0)),"") | E12: =IFERROR(INDEX(Registro!$Y$2:$Y$501,MATCH($A12&"|"&4,Registro!$X$2:$X$501,0)),"") | F12: =IFERROR(INDEX(Registro!$Y$2:$Y$501,MATCH($A12&"|"&5,Registro!$X$2:$X$501,0)),"") | G12: =IFERROR(INDEX(Registro!$Y$2:$Y$501,MATCH($A12&"|"&6,Registro!$X$2:$X$501,0)),"") | H12: =IFERROR(INDEX(Registro!$Y$2:$Y$501,MATCH($A12&"|"&7,Registro!$X$2:$X$501,0)),"") | I12: =IFERROR(INDEX(Registro!$Y$2:$Y$501,MATCH($A12&"|"&8,Registro!$X$2:$X$501,0)),"") | J12: =IFERROR(INDEX(Registro!$Y$2:$Y$501,MATCH($A12&"|"&9,Registro!$X$2:$X$501,0)),"") | K12: =IFERROR(INDEX(Registro!$Y$2:$Y$501,MATCH($A12&"|"&10,Registro!$X$2:$X$501,0)),"") | L12: =IFERROR(INDEX(Registro!$Y$2:$Y$501,MATCH($A12&"|"&11,Registro!$X$2:$X$501,0)),"") | M12: =IFERROR(INDEX(Registro!$Y$2:$Y$501,MATCH($A12&"|"&12,Registro!$X$2:$X$501,0)),"")
A13: FLAUTA TRAVERSA | B13: =IFERROR(INDEX(Registro!$Y$2:$Y$501,MATCH($A13&"|"&1,Registro!$X$2:$X$501,0)),"") | C13: =IFERROR(INDEX(Registro!$Y$2:$Y$501,MATCH($A13&"|"&2,Registro!$X$2:$X$501,0)),"") | D13: =IFERROR(INDEX(Registro!$Y$2:$Y$501,MATCH($A13&"|"&3,Registro!$X$2:$X$501,0)),"") | E13: =IFERROR(INDEX(Registro!$Y$2:$Y$501,MATCH($A13&"|"&4,Registro!$X$2:$X$501,0)),"") | F13: =IFERROR(INDEX(Registro!$Y$2:$Y$501,MATCH($A13&"|"&5,Registro!$X$2:$X$501,0)),"") | G13: =IFERROR(INDEX(Registro!$Y$2:$Y$501,MATCH($A13&"|"&6,Registro!$X$2:$X$501,0)),"") | H13: =IFERROR(INDEX(Registro!$Y$2:$Y$501,MATCH($A13&"|"&7,Registro!$X$2:$X$501,0)),"") | I13: =IFERROR(INDEX(Registro!$Y$2:$Y$501,MATCH($A13&"|"&8,Registro!$X$2:$X$501,0)),"") | J13: =IFERROR(INDEX(Registro!$Y$2:$Y$501,MATCH($A13&"|"&9,Registro!$X$2:$X$501,0)),"") | K13: =IFERROR(INDEX(Registro!$Y$2:$Y$501,MATCH($A13&"|"&10,Registro!$X$2:$X$501,0)),"") | L13: =IFERROR(INDEX(Registro!$Y$2:$Y$501,MATCH($A13&"|"&11,Registro!$X$2:$X$501,0)),"") | M13: =IFERROR(INDEX(Registro!$Y$2:$Y$501,MATCH($A13&"|"&12,Registro!$X$2:$X$501,0)),"")
